Workbook
Name BED_FOR_L20E: PO!#REF!
Name CMAcode: [1]CMA!#REF!
Name Code: [2]CMA!$A:$A
Name CodeE: IF(PO!$B1="","",VLOOKUP(PO!$B1,[2]CMA!$A:$N,3,0))
Name CodeNo: IF(PO!$B1="","",VLOOKUP(PO!$B1,[2]CMA!$A:$N,2,0))
Name CodePL: [2]CMA!$B$5:$B$1115
Name Criteria2: #REF!
Name Criteria7: #REF!
Name Database2: #REF!
Name Model: IF(PO!$C1="","",VLOOKUP(PO!$C1,'[3]CMA items'!$B:$E,2,0))
Name Name: IF(PO!$B1="","",VLOOKUP(PO!$B1,'[4]CMA items'!$B:$E,3,0))
Name PriceJ: IF(PO!$B1="","",VLOOKUP(PO!$B1,[2]CMA!$A:$N,8,0))
Name PriceU: IF(PO!$B1="","",VLOOKUP(PO!$B1,[2]CMA!$A:$N,9,0))
Name PRINT_AREA_MI: #REF!
Name WT: IF(PO!$C1="","",VLOOKUP(PO!$C1,'[3]CMA items'!$B:$E,4,0))

Sheet PO
A1: CITIZEN MACHINERY ASIA CO., LTD
A2: 199, Mu 1 Phahon Yothin Road, Sanap Tuep Sub-district,
A3: Wang Noi District, Phra Nakhon Si Ayutthaya Province 13170, Thailand
A4: Tel: 66 (0)35 902-640-1 # 807; Fax: 66 (0)35 902-644
A5: PURCHASE ORDER SHEET
C7: To: | D7: CITIZEN MACHINERY VIETNAM CO., LTD
D8: Land Plot: J2, J3, J4 Japan Haiphong Industrial Zone
D9: Hong An ward, Hai Phong city, Viet Nam
D10: Attn: Mr. Kozu Takanari - FD
D11: Tel.: +84-225-3743232~3 | E11: Fax: +84-225-3743234
D13: Purchase Order No. : | E13: 112602255;3429,3620,3655,3663
D14: Date: | E14: June 15th 2026
D16: Shipment: | E16: Ocean freight
D17: Terms of Delivery: | E17: =IF(E16="Ocean freight","CIF Laem Chabang, Thailand","FCA Hanoi") -> CIF Laem Chabang, Thailand | K17: ETD | L17: ETA
D18: Delivery Time: | E18: =CONCATENATE("On or about ",L18,L19,"",L20) -> On or about August 23rd 2026 | K18: August | L18: August
D19: Port of Discharge: | E19: Laem Chabang, Thailand | K19: 19th | L19: 23rd
D20: Insurance: | E20: Covered by Shipper | K20: 2026 | L20: 2026
D21: Payment: | E21: T/T Remittance within 30 days after Invoice date
C22: PARTS FOR CNC AUTOMATIC LATHE.
A23: Description of goods | F23: Quantity | H23: Unit Price | I23: Amount (JPY)
B24: Code No. | D24: Code Name | E24: P.O No.
A25: 1 | B25: D0188 | C25: 0618-081-4 | D25: RM BODY L12 | E25: 112603655 | F25: 5 | G25: PCS | H25: 255935 | I25: =IF(ISERROR(H25*F25),"",(F25*H25)) -> 1279675 | J25: 872 | K25: =J25*F25 -> 4360 | N25: =VLOOKUP(C25,'[5]CMA Change 1 Coating Paint'!$C$20:$J$148,8,0) -> 255935 | O25: =H25-N25 -> 0 | W25: =H25-L25 -> 255935
A26: =A25+1 -> 2 | B26: D0191 | C26: 0618-084-2 | D26: BED L220E | E26: 112603649 | F26: 3 | G26: PCS | H26: 315980 | I26: =IF(ISERROR(H26*F26),"",(F26*H26)) -> 947940 | J26: 1170 | K26: =J26*F26 -> 3510 | N26: =VLOOKUP(C26,'[5]CMA Change 1 Coating Paint'!$C$20:$J$148,8,0) -> 315980 | O26: =H26-N26 -> 0 | W26: =H26-L26 -> 315980
A27: =A26+1 -> 3 | B27: G0065 | C27: 618-084-13F | D27: BED L220E | E27: 112602255 | F27: 8 | G27: PCS | H27: 410206 | I27: =IF(ISERROR(H27*F27),"",(F27*H27)) -> 3281648 | J27: 1170 | K27: =J27*F27 -> 9360 | N27: =VLOOKUP(C27,'[5]CMA Change 1 Coating Paint'!$C$20:$J$148,8,0) -> #N/A | O27: =H27-N27 -> #N/A | W27: =H27-L27 -> 410206
A28: =A27+1 -> 4 | B28: D0067 | C28: 0618-087-2 | D28: BED L32 | E28: 112603639 | F28: 2 | G28: PCS | H28: 408610 | I28: =IF(ISERROR(H28*F28),"",(F28*H28)) -> 817220 | J28: 1375 | K28: =J28*F28 -> 2750 | N28: =VLOOKUP(C28,'[5]CMA Change 1 Coating Paint'!$C$20:$J$148,8,0) -> 408610 | O28: =H28-N28 -> 0 | W28: =H28-L28 -> 408610
A29: =A28+1 -> 5 | B29: D0189 | C29: 0618-1001-4 | D29: BED L212 | E29: 112603649 | F29: 7 | G29: PCS | H29: 341932 | I29: =IF(ISERROR(H29*F29),"",(F29*H29)) -> 2393524 | J29: 1165 | K29: =J29*F29 -> 8155 | N29: =VLOOKUP(C29,'[5]CMA Change 1 Coating Paint'!$C$20:$J$148,8,0) -> 341932 | O29: =H29-N29 -> 0 | W29: =H29-L29 -> 341932
A30: =A29+1 -> 6 | B30: G0066 | C30: 618-089-4F | D30: BED R50140 | E30: 112602939:2, 112603652:6 | F30: 8 | G30: PCS | H30: 208338 | I30: =IF(ISERROR(H30*F30),"",(F30*H30)) -> 1666704 | J30: 590 | K30: =J30*F30 -> 4720 | N30: =VLOOKUP(C30,'[5]CMA Change 1 Coating Paint'!$C$20:$J$148,8,0) -> #N/A | O30: =H30-N30 -> #N/A
A31: =A30+1 -> 7 | B31: D0071 | C31: 0618-1002-1 | D31: BED L320E | E31: 112603639:4, 112603663:10 | F31: 14 | G31: PCS | H31: 394030 | I31: =IF(ISERROR(H31*F31),"",(F31*H31)) -> 5516420 | J31: 1330 | K31: =J31*F31 -> 18620 | N31: =VLOOKUP(C31,'[5]CMA Change 1 Coating Paint'!$C$20:$J$148,8,0) -> 394030 | O31: =H31-N31 -> 0
A32: =A31+1 -> 8 | B32: G0063 | C32: 618-1005-03F | D32: BED L232 | E32: 112603429 | F32: 5 | G32: PCS | H32: 571830 | I32: =IF(ISERROR(H32*F32),"",(F32*H32)) -> 2859150 | J32: 1588 | K32: =J32*F32 -> 7940 | N32: 571830 | O32: =H32-N32 -> 0 | W32: =H32-L32 -> 571830
A33: =A32+1 -> 9 | B33: D0085 | C33: 0613-238-2 | D33: MOTOR BRACKET | E33: 112604604 | F33: 50 | G33: PCS | H33: 1920 | I33: =IF(ISERROR(H33*F33),"",(F33*H33)) -> 96000 | J33: 6 | K33: =J33*F33 -> 300 | N33: =VLOOKUP(C33,'[5]CMA Change 1 Coating Paint'!$C$20:$J$148,8,0) -> 1920 | O33: =H33-N33 -> 0
A34: =A33+1 -> 10 | B34: D0009 | C34: 0617-116-3 | D34: CROSS SLIDE | E34: 112603662 | F34: 18 | G34: PCS | H34: 14226 | I34: =IF(ISERROR(H34*F34),"",(F34*H34)) -> 256068 | J34: 46 | K34: =J34*F34 -> 828 | N34: =VLOOKUP(C34,'[5]CMA Change 1 Coating Paint'!$C$20:$J$148,8,0) -> 14226 | O34: =H34-N34 -> 0
A35: =A34+1 -> 11 | B35: G0003 | C35: 617-116-9R | D35: CROSS SLIDE | E35: 112603660 | F35: 10 | G35: PCS | H35: 32349 | I35: =IF(ISERROR(H35*F35),"",(F35*H35)) -> 323490 | J35: 46 | K35: =J35*F35 -> 460 | N35: =VLOOKUP(C35,'[5]CMA Change 1 Coating Paint'!$C$20:$J$148,8,0) -> #N/A | O35: =H35-N35 -> #N/A
A36: =A35+1 -> 12 | B36: D0146 | C36: 0614-291-1 | D36: BASE L220E | E36: 112603667 | F36: 30 | G36: PCS | H36: 2165 | I36: =IF(ISERROR(H36*F36),"",(F36*H36)) -> 64950 | J36: 7 | K36: =J36*F36 -> 210 | N36: =VLOOKUP(C36,'[5]CMA Change 1 Coating Paint'!$C$20:$J$148,8,0) -> 2165 | O36: =H36-N36 -> 0
A37: =A36+1 -> 13 | B37: D0131 | C37: 0615-478 | D37: Z2 SLIDE | E37: 112603662 | F37: 10 | G37: PCS | H37: 8806 | I37: =IF(ISERROR(H37*F37),"",(F37*H37)) -> 88060 | J37: 30 | K37: =J37*F37 -> 300 | N37: =VLOOKUP(C37,'[5]CMA Change 1 Coating Paint'!$C$20:$J$148,8,0) -> 8806 | O37: =H37-N37 -> 0
A38: =A37+1 -> 14 | B38: G0035 | C38: 615-478-4R | D38: Z2 SLIDE | E38: 112603660 | F38: 10 | G38: PCS | H38: 22788 | I38: =IF(ISERROR(H38*F38),"",(F38*H38)) -> 227880 | J38: 30 | K38: =J38*F38 -> 300 | N38: =VLOOKUP(C38,'[5]CMA Change 1 Coating Paint'!$C$20:$J$148,8,0) -> #N/A | O38: =H38-N38 -> #N/A
A39: =A38+1 -> 15 | B39: G0039 | C39: 615-509-5R | D39: HEAD STOCK | E39: 112603640:10, 112603660:5 | F39: 15 | G39: PCS | H39: 29700 | I39: =IF(ISERROR(H39*F39),"",(F39*H39)) -> 445500 | J39: 42 | K39: =J39*F39 -> 630 | N39: =VLOOKUP(C39,'[5]CMA Change 1 Coating Paint'!$C$20:$J$148,8,0) -> #N/A | O39: =H39-N39 -> #N/A
A40: =A39+1 -> 16 | B40: D0166 | C40: 0617-115-1 | D40: TOOL POST | E40: 112603657 | F40: 10 | G40: PCS | H40: 40848 | I40: =IF(ISERROR(H40*F40),"",(F40*H40)) -> 408480 | J40: 141 | K40: =J40*F40 -> 1410 | N40: =VLOOKUP(C40,'[5]CMA Change 1 Coating Paint'!$C$20:$J$148,8,0) -> 40848 | O40: =H40-N40 -> 0
A41: =A40+1 -> 17 | B41: G0052 | C41: 617-123-6R | D41: TOOL POST | E41: 112603665 | F41: 5 | G41: PCS | H41: 90030 | I41: =IF(ISERROR(H41*F41),"",(F41*H41)) -> 450150 | J41: 141 | K41: =J41*F41 -> 705 | N41: =VLOOKUP(C41,'[5]CMA Change 1 Coating Paint'!$C$20:$J$148,8,0) -> #N/A | O41: =H41-N41 -> #N/A
A42: =A41+1 -> 18 | B42: G0064 | C42: 616-432-6R | D42: X SLIDE | E42: 112603640:10, 112603660:10 | F42: 20 | G42: PCS | H42: 21919 | I42: =IF(ISERROR(H42*F42),"",(F42*H42)) -> 438380 | J42: 19 | K42: =J42*F42 -> 380 | N42: =VLOOKUP(C42,'[5]CMA Change 1 Coating Paint'!$C$20:$J$148,8,0) -> #N/A | O42: =H42-N42 -> #N/A
A43: =A42+1 -> 19 | B43: G0041 | C43: 616-398-5R | D43: CROSS SLIDE | E43: 112603650 | F43: 15 | G43: PCS | H43: 37724 | I43: =IF(ISERROR(H43*F43),"",(F43*H43)) -> 565860 | J43: 43 | K43: =J43*F43 -> 645 | N43: =VLOOKUP(C43,'[5]CMA Change 1 Coating Paint'!$C$20:$J$148,8,0) -> #N/A | O43: =H43-N43 -> #N/A
...

Sheet CMV
B1: CMV
B2: Code No. (CMV) | C2: Code Name (CMV) | D2: Code Name (CMA) | E2: grp_no | F2: upm | G2: upm IC | H2: Remark | K2: ใส่ข้อมูล | L2: ผลลัพธ์ | M2: UOM | N2: Group_No | O2: Column1
B3: 615-1036C | C3: BACK 4 SLEEVE HOLDER | D3: BACK 4-SLEEVE HOLDER | E3: =VLOOKUP(D3,[6]USE!A:D,2,0) -> 000231 | F3: =VLOOKUP(D3,[6]USE!A:E,3,0) -> PCS | G3: =VLOOKUP(D3,[6]USE!A:D,4,0) -> C62 | K3: RM BODY L12 | L3: =VLOOKUP(K3,C:F,2,0) -> BODY | M3: =VLOOKUP(L3,D:G,4,0) -> C62 | N3: =VLOOKUP(L3,D:H,2,0) -> 000001 | O3: =ROW(O1) -> 1
B4: 615-510A | C4: BACK HEAD STOCK | D4: HEAD STOCK | E4: =VLOOKUP(D4,[6]USE!A:D,2,0) -> 000206 | F4: =VLOOKUP(D4,[6]USE!A:E,3,0) -> PCS | G4: =VLOOKUP(D4,[6]USE!A:D,4,0) -> C62 | K4: BED L220E | L4: =VLOOKUP(K4,C:F,2,0) -> BED | M4: =VLOOKUP(L4,D:G,4,0) -> C62 | N4: =VLOOKUP(L4,D:H,2,0) -> 000173 | O4: =ROW(O2) -> 2
B5: 615-408-1C | C5: BACK HEAD STOCK L20 | D5: HEAD STOCK | E5: =VLOOKUP(D5,[6]USE!A:D,2,0) -> 000206 | F5: =VLOOKUP(D5,[6]USE!A:E,3,0) -> PCS | G5: =VLOOKUP(D5,[6]USE!A:D,4,0) -> C62 | K5: BED L220E | L5: =VLOOKUP(K5,C:F,2,0) -> BED | M5: =VLOOKUP(L5,D:G,4,0) -> C62 | N5: =VLOOKUP(L5,D:H,2,0) -> 000173 | O5: =ROW(O3) -> 3
B6: 616-357-3C | C6: BACK SPINDLE BASE L32 | D6: HEAD STOCK | E6: =VLOOKUP(D6,[6]USE!A:D,2,0) -> 000206 | F6: =VLOOKUP(D6,[6]USE!A:E,3,0) -> PCS | G6: =VLOOKUP(D6,[6]USE!A:D,4,0) -> C62 | K6: BED L32 | L6: =VLOOKUP(K6,C:F,2,0) -> BED | M6: =VLOOKUP(L6,D:G,4,0) -> C62 | N6: =VLOOKUP(L6,D:H,2,0) -> 000173 | O6: =ROW(O4) -> 4
B7: 614-291-1C | C7: BASE L220E | D7: GUIDE BUSH BASE | E7: 000213 | F7: =VLOOKUP(D7,[6]USE!A:E,3,0) -> PCS | G7: =VLOOKUP(D7,[6]USE!A:D,4,0) -> C62 | K7: BED L212 | L7: =VLOOKUP(K7,C:F,2,0) -> BED | M7: =VLOOKUP(L7,D:G,4,0) -> C62 | N7: =VLOOKUP(L7,D:H,2,0) -> 000173 | O7: =ROW(O5) -> 5
B8: 614-291-1 | C8: BASE | D8: GUIDE BUSH BASE | E8: 000213 | F8: =VLOOKUP(D8,[6]USE!A:E,3,0) -> PCS | G8: =VLOOKUP(D8,[6]USE!A:D,4,0) -> C62 | K8: BED R50140 | L8: =VLOOKUP(K8,C:F,2,0) -> BED | M8: =VLOOKUP(L8,D:G,4,0) -> C62 | N8: =VLOOKUP(L8,D:H,2,0) -> 000173 | O8: =ROW(O6) -> 6
B9: 618-084-12 | C9: BED FOR L220E | D9: BED | E9: =VLOOKUP(D9,[6]USE!A:D,2,0) -> 000173 | F9: =VLOOKUP(D9,[6]USE!A:E,3,0) -> PCS | G9: =VLOOKUP(D9,[6]USE!A:D,4,0) -> C62 | K9: BED L320E | L9: =VLOOKUP(K9,C:F,2,0) -> BED | M9: =VLOOKUP(L9,D:G,4,0) -> C62 | N9: =VLOOKUP(L9,D:H,2,0) -> 000173 | O9: =ROW(O6) -> 6
B10: 618-084-2C | C10: BED FOR L220E | D10: BED | E10: =VLOOKUP(D10,[6]USE!A:D,2,0) -> 000173 | F10: =VLOOKUP(D10,[6]USE!A:E,3,0) -> PCS | G10: =VLOOKUP(D10,[6]USE!A:D,4,0) -> C62 | K10: BED L232 | L10: =VLOOKUP(K10,C:F,2,0) -> BED | M10: =VLOOKUP(L10,D:G,4,0) -> C62 | N10: =VLOOKUP(L10,D:H,2,0) -> 000173 | O10: =ROW(O7) -> 7
B11: 618-1001-4C | C11: BED L212 | D11: BED | E11: =VLOOKUP(D11,[6]USE!A:D,2,0) -> 000173 | F11: =VLOOKUP(D11,[6]USE!A:E,3,0) -> PCS | G11: =VLOOKUP(D11,[6]USE!A:D,4,0) -> C62 | K11: MOTOR BRACKET | L11: =VLOOKUP(K11,C:F,2,0) -> MOTOR BRACKET | M11: =VLOOKUP(L11,D:G,4,0) -> C62 | N11: =VLOOKUP(L11,D:H,2,0) -> 000003 | O11: =ROW(O9) -> 9
B12: 618-084-13 | C12: BED L220E | D12: BED | E12: =VLOOKUP(D12,[6]USE!A:D,2,0) -> 000173 | F12: =VLOOKUP(D12,[6]USE!A:E,3,0) -> PCS | G12: =VLOOKUP(D12,[6]USE!A:D,4,0) -> C62 | K12: CROSS SLIDE | L12: =VLOOKUP(K12,C:F,2,0) -> CROSS SLIDE | M12: =VLOOKUP(L12,D:G,4,0) -> C62 | N12: =VLOOKUP(L12,D:H,2,0) -> 000002 | O12: =ROW(O10) -> 10
B13: 618-087-2C | C13: BED L32 | D13: BED | E13: =VLOOKUP(D13,[6]USE!A:D,2,0) -> 000173 | F13: =VLOOKUP(D13,[6]USE!A:E,3,0) -> PCS | G13: =VLOOKUP(D13,[6]USE!A:D,4,0) -> C62 | K13: CROSS SLIDE | L13: =VLOOKUP(K13,C:F,2,0) -> CROSS SLIDE | M13: =VLOOKUP(L13,D:G,4,0) -> C62 | N13: =VLOOKUP(L13,D:H,2,0) -> 000002 | O13: =ROW(O11) -> 11
B14: 618-1002-1C | C14: BED L320E | D14: BED | E14: =VLOOKUP(D14,[6]USE!A:D,2,0) -> 000173 | F14: =VLOOKUP(D14,[6]USE!A:E,3,0) -> PCS | G14: =VLOOKUP(D14,[6]USE!A:D,4,0) -> C62 | K14: BASE L220E | L14: =VLOOKUP(K14,C:F,2,0) -> GUIDE BUSH BASE | M14: =VLOOKUP(L14,D:G,4,0) -> C62 | N14: =VLOOKUP(L14,D:H,2,0) -> 000213 | O14: =ROW(O12) -> 12
B15: 618-089-4F | C15: BED R50140 | D15: BED | E15: =VLOOKUP(D15,[6]USE!A:D,2,0) -> 000173 | F15: =VLOOKUP(D15,[6]USE!A:E,3,0) -> PCS | G15: =VLOOKUP(D15,[6]USE!A:D,4,0) -> C62 | K15: Z2 SLIDE | L15: =VLOOKUP(K15,C:F,2,0) -> Z2 SLIDE | M15: =VLOOKUP(L15,D:G,4,0) -> C62 | N15: =VLOOKUP(L15,D:H,2,0) -> 000175 | O15: =ROW(O13) -> 13
B16: 613-242C | C16: BLOCK A320N | D16: =VLOOKUP(B16,[7]IV!$B$21:$C$80,2,0) -> BLOCK | E16: =VLOOKUP(D16,[6]USE!A:D,2,0) -> 000013 | F16: =VLOOKUP(D16,[6]USE!A:E,3,0) -> PCS | G16: =VLOOKUP(D16,[6]USE!A:D,4,0) -> C62 | K16: Z2 SLIDE | L16: =VLOOKUP(K16,C:F,2,0) -> Z2 SLIDE | M16: =VLOOKUP(L16,D:G,4,0) -> C62 | N16: =VLOOKUP(L16,D:H,2,0) -> 000175 | O16: =ROW(O14) -> 14
B17: 615-470C | C17: BRACKET | D17: =VLOOKUP(B17,[7]IV!$B$21:$C$80,2,0) -> BRACKET | E17: =VLOOKUP(D17,[6]USE!A:D,2,0) -> 000006 | F17: =VLOOKUP(D17,[6]USE!A:E,3,0) -> PCS | G17: =VLOOKUP(D17,[6]USE!A:D,4,0) -> C62 | K17: HEAD STOCK | L17: =VLOOKUP(K17,C:F,2,0) -> HEAD STOCK | M17: =VLOOKUP(L17,D:G,4,0) -> C62 | N17: =VLOOKUP(L17,D:H,2,0) -> 000206 | O17: =ROW(O15) -> 15
B18: 615-512-1C | C18: BRACKET | D18: BRACKET | E18: =VLOOKUP(D18,[6]USE!A:D,2,0) -> 000006 | F18: =VLOOKUP(D18,[6]USE!A:E,3,0) -> PCS | G18: =VLOOKUP(D18,[6]USE!A:D,4,0) -> C62 | K18: TOOL POST | L18: =VLOOKUP(K18,C:F,2,0) -> TOOL POST | M18: =VLOOKUP(L18,D:G,4,0) -> C62 | N18: =VLOOKUP(L18,D:H,2,0) -> 000174 | O18: =ROW(O16) -> 16
B19: 616-396-2C | C19: BRACKET | D19: BRACKET | E19: =VLOOKUP(D19,[6]USE!A:D,2,0) -> 000006 | F19: =VLOOKUP(D19,[6]USE!A:E,3,0) -> PCS | G19: =VLOOKUP(D19,[6]USE!A:D,4,0) -> C62 | K19: TOOL POST | L19: =VLOOKUP(K19,C:F,2,0) -> TOOL POST | M19: =VLOOKUP(L19,D:G,4,0) -> C62 | N19: =VLOOKUP(L19,D:H,2,0) -> 000174 | O19: =ROW(O17) -> 17
B20: 614-286-1C | C20: BRACKET 1/2 L12 | D20: BRACKET | E20: =VLOOKUP(D20,[6]USE!A:D,2,0) -> 000006 | F20: =VLOOKUP(D20,[6]USE!A:E,3,0) -> PCS | G20: =VLOOKUP(D20,[6]USE!A:D,4,0) -> C62 | K20: X SLIDE | L20: =VLOOKUP(K20,C:F,2,0) -> X-SLIDE | M20: =VLOOKUP(L20,D:G,4,0) -> C62 | N20: =VLOOKUP(L20,D:H,2,0) -> 000004 | O20: =ROW(O18) -> 18
B21: 615-467-1C | C21: BRACKET 1/2 L12 | D21: =VLOOKUP(B21,[7]IV!$B$21:$C$80,2,0) -> BRACKET | E21: =VLOOKUP(D21,[6]USE!A:D,2,0) -> 000006 | F21: =VLOOKUP(D21,[6]USE!A:E,3,0) -> PCS | G21: =VLOOKUP(D21,[6]USE!A:D,4,0) -> C62 | K21: CROSS SLIDE | L21: =VLOOKUP(K21,C:F,2,0) -> CROSS SLIDE | M21: =VLOOKUP(L21,D:G,4,0) -> C62 | N21: =VLOOKUP(L21,D:H,2,0) -> 000002 | O21: =ROW(O19) -> 19
B22: 616-370-1C | C22: BRACKET B1216E | D22: BRACKET | E22: =VLOOKUP(D22,[6]USE!A:D,2,0) -> 000006 | F22: =VLOOKUP(D22,[6]USE!A:E,3,0) -> PCS | G22: =VLOOKUP(D22,[6]USE!A:D,4,0) -> C62 | K22: BACK HEAD STOCK | L22: =VLOOKUP(K22,C:F,2,0) -> HEAD STOCK | M22: =VLOOKUP(L22,D:G,4,0) -> C62 | N22: =VLOOKUP(L22,D:H,2,0) -> 000206 | O22: =ROW(O20) -> 20
B23: 616-385C | C23: BRACKET L12 | D23: =VLOOKUP(B23,[7]IV!$B$21:$C$80,2,0) -> BRACKET | E23: =VLOOKUP(D23,[6]USE!A:D,2,0) -> 000006 | F23: =VLOOKUP(D23,[6]USE!A:E,3,0) -> PCS | G23: =VLOOKUP(D23,[6]USE!A:D,4,0) -> C62 | K23: CHUCKING LEVER A320N | L23: =VLOOKUP(K23,C:F,2,0) -> CHUCKING LEVER | M23: =VLOOKUP(L23,D:G,4,0) -> C62 | N23: =VLOOKUP(L23,D:H,2,0) -> 000084 | O23: =ROW(O21) -> 21
B24: 614-220C | C24: CHUCKING LEVER L12 | D24: =VLOOKUP(B24,[7]IV!$B$21:$C$80,2,0) -> CHUCKING LEVER | E24: =VLOOKUP(D24,[6]USE!A:D,2,0) -> 000084 | F24: =VLOOKUP(D24,[6]USE!A:E,3,0) -> PCS | G24: =VLOOKUP(D24,[6]USE!A:D,4,0) -> C62 | K24: SLEEVE HOLDER | L24: =VLOOKUP(K24,C:F,2,0) -> SLEEVE HOLDER | M24: =VLOOKUP(L24,D:G,4,0) -> C62 | N24: =VLOOKUP(L24,D:H,2,0) -> 000119 | O24: =ROW(O22) -> 22
B25: 614-272-1C | C25: CHUCKING LEVER L12 | D25: CHUCKING LEVER | E25: =VLOOKUP(D25,[6]USE!A:D,2,0) -> 000084 | F25: =VLOOKUP(D25,[6]USE!A:E,3,0) -> PCS | G25: =VLOOKUP(D25,[6]USE!A:D,4,0) -> C62 | K25: HEAD STOCK BRACKET | L25: =VLOOKUP(K25,C:F,2,0) -> BRACKET | M25: =VLOOKUP(L25,D:G,4,0) -> C62 | N25: =VLOOKUP(L25,D:H,2,0) -> 000006 | O25: =ROW(O23) -> 23
B26: 615-481C | C26: CHUCKING LEVER A320N | D26: CHUCKING LEVER | E26: =VLOOKUP(D26,[6]USE!A:D,2,0) -> 000084 | F26: =VLOOKUP(D26,[6]USE!A:E,3,0) -> PCS | G26: =VLOOKUP(D26,[6]USE!A:D,4,0) -> C62 | K26: HEAD STOCK L32 | L26: =VLOOKUP(K26,C:F,2,0) -> HEAD STOCK | M26: =VLOOKUP(L26,D:G,4,0) -> C62 | N26: =VLOOKUP(L26,D:H,2,0) -> 000206 | O26: =ROW(O24) -> 24
B27: 615-426-2C | C27: CHUCKING LEVER L32 | D27: CHUCKING LEVER | E27: =VLOOKUP(D27,[6]USE!A:D,2,0) -> 000084 | F27: =VLOOKUP(D27,[6]USE!A:E,3,0) -> PCS | G27: =VLOOKUP(D27,[6]USE!A:D,4,0) -> C62 | K27: TOOL POST L32 | L27: =VLOOKUP(K27,C:F,2,0) -> TOOL POST | M27: =VLOOKUP(L27,D:G,4,0) -> C62 | N27: =VLOOKUP(L27,D:H,2,0) -> 000174 | O27: =ROW(O25) -> 25
B28: 616-398-4A | C28: CROSS SLIDE | D28: CROSS SLIDE | E28: =VLOOKUP(D28,[6]USE!A:D,2,0) -> 000002 | F28: =VLOOKUP(D28,[6]USE!A:E,3,0) -> PCS | G28: =VLOOKUP(D28,[6]USE!A:D,4,0) -> C62 | K28: TOOL POST | L28: =VLOOKUP(K28,C:F,2,0) -> TOOL POST | M28: =VLOOKUP(L28,D:G,4,0) -> C62 | N28: =VLOOKUP(L28,D:H,2,0) -> 000174 | O28: =ROW(O26) -> 26
B29: 617-116-2C | C29: CROSS SLIDE | D29: CROSS SLIDE | E29: =VLOOKUP(D29,[6]USE!A:D,2,0) -> 000002 | F29: =VLOOKUP(D29,[6]USE!A:E,3,0) -> PCS | G29: =VLOOKUP(D29,[6]USE!A:D,4,0) -> C62 | K29: X1 SLIDE L32 | L29: =VLOOKUP(K29,C:F,2,0) -> X-SLIDE | M29: =VLOOKUP(L29,D:G,4,0) -> C62 | N29: =VLOOKUP(L29,D:H,2,0) -> 000004 | O29: =ROW(O27) -> 27
B30: 617-116-8A | C30: CROSS SLIDE | D30: CROSS SLIDE | E30: =VLOOKUP(D30,[6]USE!A:D,2,0) -> 000002 | F30: =VLOOKUP(D30,[6]USE!A:E,3,0) -> PCS | G30: =VLOOKUP(D30,[6]USE!A:D,4,0) -> C62 | K30: Z2 SLIDE L32 | L30: =VLOOKUP(K30,C:F,2,0) -> Z2 SLIDE | M30: =VLOOKUP(L30,D:G,4,0) -> C62 | N30: =VLOOKUP(L30,D:H,2,0) -> 000175 | O30: =ROW(O28) -> 28
B31: 617-116-9A | C31: CROSS SLIDE | D31: CROSS SLIDE | E31: =VLOOKUP(D31,[6]USE!A:D,2,0) -> 000002 | F31: =VLOOKUP(D31,[6]USE!A:E,3,0) -> PCS | G31: =VLOOKUP(D31,[6]USE!A:D,4,0) -> C62 | K31: Y2 AXIS BASE L32 | L31: =VLOOKUP(K31,C:F,2,0) -> Y-SLIDE | M31: =VLOOKUP(L31,D:G,4,0) -> C62 | N31: =VLOOKUP(L31,D:H,2,0) -> 000186 | O31: =ROW(O29) -> 29
B32: 617-118-2C | C32: CROSS SLIDE L220E | D32: CROSS SLIDE | E32: =VLOOKUP(D32,[6]USE!A:D,2,0) -> 000002 | F32: =VLOOKUP(D32,[6]USE!A:E,3,0) -> PCS | G32: =VLOOKUP(D32,[6]USE!A:D,4,0) -> C62 | K32: Y2 AXIS BASE | L32: =VLOOKUP(K32,C:F,2,0) -> Y-SLIDE | M32: =VLOOKUP(L32,D:G,4,0) -> C62 | N32: =VLOOKUP(L32,D:H,2,0) -> 000186 | O32: =ROW(O30) -> 30
B33: 616-240C | C33: CROSS SLIDE B1216E | D33: CROSS SLIDE | E33: =VLOOKUP(D33,[6]USE!A:D,2,0) -> 000002 | F33: =VLOOKUP(D33,[6]USE!A:E,3,0) -> PCS | G33: =VLOOKUP(D33,[6]USE!A:D,4,0) -> C62 | K33: HEAD STOCK | L33: =VLOOKUP(K33,C:F,2,0) -> HEAD STOCK | M33: =VLOOKUP(L33,D:G,4,0) -> C62 | N33: =VLOOKUP(L33,D:H,2,0) -> 000206 | O33: =ROW(O31) -> 31
B34: 616-386-1C | C34: CROSS SLIDE FOR L12 | D34: CROSS SLIDE | E34: =VLOOKUP(D34,[6]USE!A:D,2,0) -> 000002 | F34: =VLOOKUP(D34,[6]USE!A:E,3,0) -> PCS | G34: =VLOOKUP(D34,[6]USE!A:D,4,0) -> C62 | K34: MOTOR HOUSING | L34: =VLOOKUP(K34,C:F,2,0) -> MOTOR HOUSING | M34: =VLOOKUP(L34,D:G,4,0) -> C62 | N34: =VLOOKUP(L34,D:H,2,0) -> 000187 | O34: =ROW(O32) -> 32
B35: 616-387-3C | C35: CROSS SLIDE FOR L12 | D35: CROSS SLIDE | E35: =VLOOKUP(D35,[6]USE!A:D,2,0) -> 000002 | F35: =VLOOKUP(D35,[6]USE!A:E,3,0) -> PCS | G35: =VLOOKUP(D35,[6]USE!A:D,4,0) -> C62 | K35: CROSS SLIDE L32 | L35: =VLOOKUP(K35,C:F,2,0) -> CROSS SLIDE | M35: =VLOOKUP(L35,D:G,4,0) -> C62 | N35: =VLOOKUP(L35,D:H,2,0) -> 000002 | O35: =ROW(O33) -> 33
B36: 617-118-2C | C36: CROSS SLIDE FOR L220E | D36: =VLOOKUP(B36,[7]IV!$B$21:$C$80,2,0) -> CROSS SLIDE | E36: =VLOOKUP(D36,[6]USE!A:D,2,0) -> 000002 | F36: =VLOOKUP(D36,[6]USE!A:E,3,0) -> PCS | G36: =VLOOKUP(D36,[6]USE!A:D,4,0) -> C62 | K36: RM CHUCKING LEVER | L36: =VLOOKUP(K36,C:F,2,0) -> CHUCKING LEVER | M36: =VLOOKUP(L36,D:G,4,0) -> C62 | N36: =VLOOKUP(L36,D:H,2,0) -> 000084 | O36: =ROW(O34) -> 34
B37: 617-118-7A | C37: CROSS SLIDE FOR L220E | D37: CROSS SLIDE | E37: =VLOOKUP(D37,[6]USE!A:D,2,0) -> 000002 | F37: =VLOOKUP(D37,[6]USE!A:E,3,0) -> PCS | G37: =VLOOKUP(D37,[6]USE!A:D,4,0) -> C62 | K37: CHUCKING LEVER L32 | L37: =VLOOKUP(K37,C:F,2,0) -> CHUCKING LEVER | M37: =VLOOKUP(L37,D:G,4,0) -> C62 | N37: =VLOOKUP(L37,D:H,2,0) -> 000084 | O37: =ROW(O35) -> 35
B38: 616-386-1C | C38: CROSS SLIDE L12 | D38: CROSS SLIDE | E38: =VLOOKUP(D38,[6]USE!A:D,2,0) -> 000002 | F38: =VLOOKUP(D38,[6]USE!A:E,3,0) -> PCS | G38: =VLOOKUP(D38,[6]USE!A:D,4,0) -> C62 | K38: TOOL POST L212 | L38: =VLOOKUP(K38,C:F,2,0) -> TOOL POST | M38: =VLOOKUP(L38,D:G,4,0) -> C62 | N38: =VLOOKUP(L38,D:H,2,0) -> 000174 | O38: =ROW(O36) -> 36
B39: 616-387-3C | C39: CROSS SLIDE L12 | D39: CROSS SLIDE | E39: =VLOOKUP(D39,[6]USE!A:D,2,0) -> 000002 | F39: =VLOOKUP(D39,[6]USE!A:E,3,0) -> PCS | G39: =VLOOKUP(D39,[6]USE!A:D,4,0) -> C62 | K39: CROSS SLIDE L212 | L39: =VLOOKUP(K39,C:F,2,0) -> CROSS SLIDE | M39: =VLOOKUP(L39,D:G,4,0) -> C62 | N39: =VLOOKUP(L39,D:H,2,0) -> 000002 | O39: =ROW(O37) -> 37
B40: 616-0019C | C40: CROSS SLIDE L212 | D40: =VLOOKUP(B40,[7]IV!$B$21:$C$80,2,0) -> CROSS SLIDE | E40: =VLOOKUP(D40,[6]USE!A:D,2,0) -> 000002 | F40: =VLOOKUP(D40,[6]USE!A:E,3,0) -> PCS | G40: =VLOOKUP(D40,[6]USE!A:D,4,0) -> C62 | K40: CROSS SLIDE L212 | L40: =VLOOKUP(K40,C:F,2,0) -> CROSS SLIDE | M40: =VLOOKUP(L40,D:G,4,0) -> C62 | N40: =VLOOKUP(L40,D:H,2,0) -> 000002 | O40: =ROW(O38) -> 38
...

Sheet IV
A1: CITIZEN MACHINERY VIETNAM CO., LTD
A2: Land plot J2, J3, J4, Japan Hai Phong IZ, Hong An ward, Hai Phong city, Viet Nam
A3: Tel: 84-225-3743232, 33 Fax: 84-225-3743234
A4: Account: (JPY) 155756, or (USD) 237132 at MUFG Bank, Ltd - Hanoi Branch
A6: INVOICE
B8: By order and for account and risk of: | H8: Invoice No.: | I8: CMV/INV26-103
B9: Consignee: | C9: CITIZEN MACHINERY ASIA CO., LTD | H9: Invoice date: | I9: 46252
B10: 199, Mu 1 Phahon Yothin Road, Sanap Tuep Sub-district, | H10: Contract (P.O) No.: 112602255;3429,3620,3655,3663
B11: Wang Noi District, Phra Nakhon Si Ayutthaya Province 13170, Thailand | H11: =CONCATENATE( "Contract (P.O date.: ", PO!E14) -> Contract (P.O date.: June 15th 2026
B12: Tel: 66 (0)35 902-640-1 # 807; Fax: 66 (0)35 902-644 | H12: Delivery Terms: CIF Laem Chabang, Thailand
H13: =CONCATENATE( "ETA Laem Chabang: ", PO!E18) -> ETA Laem Chabang: On or about August 23rd 2026
B14: Name of vessel/Voy. | C14: HF LUCKY 2617S | H14: Terms of Payment:
B15: Sailing on: | C15: =CONCATENATE(PO!K18,PO!K19,PO!K20) -> August 19th 2026 | I15: By T.T within 30 days after Invoice date
B16: Port of loading: | C16: Haiphong, Vietnam | H16: Insurance: To be covered by Shipper
B17: Port of discharge: | C17: Laem Chabang, Thailand | H17: Packing: Standard export packing
A19: No | C19: Description of goods | E19: P.O No. | F19: Quantity | H19: Unit Price | I19: Amount (JPY)
A20: =PO!C22 -> PARTS FOR CNC AUTOMATIC LATHE.
A21: 1 | B21: 0618-081-4 | C21: BODY | E21: 112603655 | F21: 5 | G21: PCS | H21: 255935 | I21: =IF(ISERROR(H21*F21),"",(H21*F21)) -> 1279675 | L21: =VLOOKUP(B21:B77,PO!C25:J81,8,0)*F21 -> 4360
A22: 2 | B22: 0618-084-2 | C22: BED | E22: 112603649 | F22: 3 | G22: PCS | H22: 315980 | I22: =IF(ISERROR(H22*F22),"",(H22*F22)) -> 947940 | L22: =VLOOKUP(B22:B78,PO!C26:J82,8,0)*F22 -> 3510
A23: 3 | B23: 618-084-13F | C23: BED | E23: 112602255 | F23: 8 | G23: PCS | H23: 410206 | I23: =IF(ISERROR(H23*F23),"",(H23*F23)) -> 3281648 | L23: =VLOOKUP(B23:B79,PO!C27:J96,8,0)*F23 -> 9360
A24: 4 | B24: 0618-087-2 | C24: BED | E24: 112603639 | F24: 2 | G24: PCS | H24: 408610 | I24: =IF(ISERROR(H24*F24),"",(H24*F24)) -> 817220 | L24: =VLOOKUP(B24:B80,PO!C28:J97,8,0)*F24 -> 2750
A25: 5 | B25: 0618-1001-4 | C25: BED | E25: 112603649 | F25: 7 | G25: PCS | H25: 341932 | I25: =IF(ISERROR(H25*F25),"",(H25*F25)) -> 2393524 | L25: =VLOOKUP(B25:B81,PO!C29:J98,8,0)*F25 -> 8155
A26: 6 | B26: 618-089-4F | C26: BED | E26: 112602939:2, 112603652:6 | F26: 8 | G26: PCS | H26: 208338 | I26: =IF(ISERROR(H26*F26),"",(H26*F26)) -> 1666704 | L26: =VLOOKUP(B26:B82,PO!C30:J99,8,0)*F26 -> 4720
A27: 7 | B27: 0618-1002-1 | C27: BED | E27: 112603639:4, 112603663:10 | F27: 14 | G27: PCS | H27: 394030 | I27: =IF(ISERROR(H27*F27),"",(H27*F27)) -> 5516420 | L27: =VLOOKUP(B27:B83,PO!C31:J100,8,0)*F27 -> 18620
A28: 8 | B28: 618-1005-03F | C28: BED | E28: 112603429 | F28: 5 | G28: PCS | H28: 571830 | I28: =IF(ISERROR(H28*F28),"",(H28*F28)) -> 2859150 | L28: =VLOOKUP(B28:B84,PO!C32:J101,8,0)*F28 -> 7940
A29: 9 | B29: 0613-238-2 | C29: MOTOR BRACKET | E29: 112604604 | F29: 50 | G29: PCS | H29: 1920 | I29: =IF(ISERROR(H29*F29),"",(H29*F29)) -> 96000 | L29: =VLOOKUP(B29:B85,PO!C33:J102,8,0)*F29 -> 300
A30: 10 | B30: 0617-116-3 | C30: CROSS SLIDE | E30: 112603662 | F30: 18 | G30: PCS | H30: 14226 | I30: =IF(ISERROR(H30*F30),"",(H30*F30)) -> 256068 | L30: =VLOOKUP(B30:B105,PO!C34:J103,8,0)*F30 -> 828
A31: 11 | B31: 617-116-9R | C31: CROSS SLIDE | E31: 112603660 | F31: 10 | G31: PCS | H31: 32349 | I31: =IF(ISERROR(H31*F31),"",(H31*F31)) -> 323490 | L31: =VLOOKUP(B31:B106,PO!C35:J104,8,0)*F31 -> 460
A32: 12 | B32: 0614-291-1 | C32: GUIDE BUSH BASE | E32: 112603667 | F32: 30 | G32: PCS | H32: 2165 | I32: =IF(ISERROR(H32*F32),"",(H32*F32)) -> 64950 | L32: =VLOOKUP(B32:B107,PO!C36:J105,8,0)*F32 -> 210
A33: 13 | B33: 0615-478 | C33: Z2 SLIDE | E33: 112603662 | F33: 10 | G33: PCS | H33: 8806 | I33: =IF(ISERROR(H33*F33),"",(H33*F33)) -> 88060 | L33: =VLOOKUP(B33:B108,PO!C37:J106,8,0)*F33 -> 300
A34: 14 | B34: 615-478-4R | C34: Z2 SLIDE | E34: 112603660 | F34: 10 | G34: PCS | H34: 22788 | I34: =IF(ISERROR(H34*F34),"",(H34*F34)) -> 227880 | L34: =VLOOKUP(B34:B109,PO!C38:J107,8,0)*F34 -> 300
A35: 15 | B35: 615-509-5R | C35: HEAD STOCK | E35: 112603640:10, 112603660:5 | F35: 15 | G35: PCS | H35: 29700 | I35: =IF(ISERROR(H35*F35),"",(H35*F35)) -> 445500 | L35: =VLOOKUP(B35:B110,PO!C39:J108,8,0)*F35 -> 630
A36: 16 | B36: 0617-115-1 | C36: TOOL POST | E36: 112603657 | F36: 10 | G36: PCS | H36: 40848 | I36: =IF(ISERROR(H36*F36),"",(H36*F36)) -> 408480 | L36: =VLOOKUP(B36:B111,PO!C40:J109,8,0)*F36 -> 1410
A37: 17 | B37: 617-123-6R | C37: TOOL POST | E37: 112603665 | F37: 5 | G37: PCS | H37: 90030 | I37: =IF(ISERROR(H37*F37),"",(H37*F37)) -> 450150 | L37: =VLOOKUP(B37:B112,PO!C41:J110,8,0)*F37 -> 705
A38: 18 | B38: 616-432-6R | C38: X-SLIDE | E38: 112603640:10, 112603660:10 | F38: 20 | G38: PCS | H38: 21919 | I38: =IF(ISERROR(H38*F38),"",(H38*F38)) -> 438380 | L38: =VLOOKUP(B38:B113,PO!C42:J111,8,0)*F38 -> 380
A39: 19 | B39: 616-398-5R | C39: CROSS SLIDE | E39: 112603650 | F39: 15 | G39: PCS | H39: 37724 | I39: =IF(ISERROR(H39*F39),"",(H39*F39)) -> 565860 | L39: =VLOOKUP(B39:B114,PO!C43:J112,8,0)*F39 -> 645
A40: 20 | B40: 615-510R | C40: HEAD STOCK | E40: 112603640:11, 112603660:5 | F40: 16 | G40: PCS | H40: 25747 | I40: =IF(ISERROR(H40*F40),"",(H40*F40)) -> 411952 | L40: =VLOOKUP(B40:B115,PO!C44:J113,8,0)*F40 -> 592
A41: 21 | B41: 0615-481 | C41: CHUCKING LEVER | E41: 112603662 | F41: 50 | G41: PCS | H41: 1387 | I41: =IF(ISERROR(H41*F41),"",(H41*F41)) -> 69350 | L41: =VLOOKUP(B41:B116,PO!C45:J114,8,0)*F41 -> 150
A42: 22 | B42: 0616-301-1 | C42: SLEEVE HOLDER | E42: 112603646 | F42: 30 | G42: PCS | H42: 4846 | I42: =IF(ISERROR(H42*F42),"",(H42*F42)) -> 145380 | L42: =VLOOKUP(B42:B117,PO!C46:J115,8,0)*F42 -> 390
A43: 23 | B43: 0615-1034-1 | C43: BRACKET | E43: 112603638:10, 112603662:20 | F43: 30 | G43: PCS | H43: 4304 | I43: =IF(ISERROR(H43*F43),"",(H43*F43)) -> 129120 | L43: =VLOOKUP(B43:B118,PO!C47:J116,8,0)*F43 -> 390
...

Sheet PL
A1: CITIZEN MACHINERY VIETNAM CO., LTD | T1: Case | U1: M3 | V1: Case | W1: M3 | X1: Case | Y1: M3 | Z1: Case | AA1: M3 | AB1: Case | AC1: M3 | AD1: Case | AE1: M3
A2: =IV!A2 -> Land plot J2, J3, J4, Japan Hai Phong IZ, Hong An ward, Hai Phong city, Viet Nam | N2: Kich thuoc thung | O2: Trong luong | Q2: So thung | R2: M3 | T2: Cont1 | U2: Cont1 | V2: Cont2 | W2: Cont2 | X2: Cont3 | Y2: Cont3 | Z2: Cont4 | AA2: Cont4 | AB2: Cont5 | AC2: Cont5 | AD2: Cont6 | AE2: Cont6
A3: Tel: 84-225-3743232, 33 Fax: 84-225-3743234
N4: 1100*770*670 | O4: 39 | P4: kg | Q4: =T4+V4+X4 -> 29 | R4: 0.57 | T4: 8 | U4: =T4*R4 -> 4.56 | V4: 8 | W4: =V4*R4 -> 4.56 | X4: 13 | Y4: =X4*R4 -> 7.41 | Z4: 16 | AA4: =Z4*R4 -> 9.12 | AC4: =R4*AB4 -> 0 | AE4: =AD4*R4 -> 0
A5: PACKING LIST | N5: 618-084-13F | O5: 8 | P5: kg | Q5: =SUMIF($B$19:$B$93,N5,$E$19:$E$123) -> 8 | R5: 1 | U5: =T5*R5 -> 0 | W5: =V5*R5 -> 0 | Y5: =X5*R5 -> 0 | AA5: =Z5*R5 -> 0 | AC5: =R5*AB5 -> 0 | AE5: =AD5*R5 -> 0
B6: By order and for account and risk of: | N6: 618-089-4 | O6: 8 | P6: kg | Q6: =SUMIF($B$19:$B$93,N6,$E$19:$E$123) -> 0 | R6: 1.12 | T6: 8 | U6: =T6*R6 -> 8.96 | W6: =V6*R6 -> 0 | Y6: =X6*R6 -> 0 | AA6: =Z6*R6 -> 0 | AC6: =R6*AB6 -> 0 | AE6: =AD6*R6 -> 0
B7: Consignee: | C7: CITIZEN MACHINERY ASIA CO., LTD. | G7: =IV!H8 -> Invoice No.: | H7: =IV!I8 -> CMV/INV26-103 | N7: 0618-1001-4 | O7: 8 | P7: kg | Q7: =SUMIF($B$19:$B$93,N7,$E$19:$E$123) -> 7 | R7: 1.65 | U7: =T7*R7 -> 0 | W7: =V7*R7 -> 0 | X7: 7 | Y7: =X7*R7 -> 11.55 | AA7: =Z7*R7 -> 0 | AC7: =R7*AB7 -> 0 | AE7: =AD7*R7 -> 0
B8: =IV!B10 -> 199, Mu 1 Phahon Yothin Road, Sanap Tuep Sub-district, | G8: =IV!H9 -> Invoice date: | H8: =IV!I9 -> 46252 | N8: 0617-107-1 | O8: 8 | P8: kg | Q8: =SUMIF($B$19:$B$93,N8,$E$19:$E$123) -> 0 | R8: 1.12 | U8: =T8*R8 -> 0 | W8: =V8*R8 -> 0 | Y8: =X8*R8 -> 0 | AA8: =Z8*R8 -> 0 | AC8: =R8*AB8 -> 0 | AE8: =AD8*R8 -> 0
B9: =IV!B11 -> Wang Noi District, Phra Nakhon Si Ayutthaya Province 13170, Thailand | G9: =CONCATENATE("Contract (P.O) No.: ", PO!E13) -> Contract (P.O) No.: 112602255;3429,3620,3655,3663 | N9: 0618-081-4 | O9: 8 | P9: kg | Q9: =SUMIF($B$19:$B$93,N9,$E$19:$E$123) -> 5 | R9: 1.2 | U9: =T9*R9 -> 0 | W9: =V9*R9 -> 0 | X9: 5 | Y9: =X9*R9 -> 6 | AA9: =Z9*R9 -> 0 | AC9: =R9*AB9 -> 0 | AE9: =AD9*R9 -> 0
B10: =IV!B12 -> Tel: 66 (0)35 902-640-1 # 807; Fax: 66 (0)35 902-644 | G10: =IV!H11 -> Contract (P.O date.: June 15th 2026 | N10: 0618-084-2 | O10: 8 | P10: kg | Q10: =SUMIF($B$19:$B$93,N10,$E$19:$E$123) -> 3 | R10: 1.2 | U10: =T10*R10 -> 0 | W10: =V10*R10 -> 0 | Y10: =X10*R10 -> 0 | Z10: 3 | AA10: =Z10*R10 -> 3.6 | AC10: =R10*AB10 -> 0 | AE10: =AD10*R10 -> 0
G11: Delivery Terms: CIF Laem Chabang, Thailand | N11: 0618-084-9 | O11: 8 | P11: kg | Q11: =SUMIF($B$19:$B$93,N11,$E$19:$E$123) -> 0 | R11: 1.2 | U11: =T11*R11 -> 0 | W11: =V11*R11 -> 0 | Y11: =X11*R11 -> 0 | AA11: =Z11*R11 -> 0 | AC11: =R11*AB11 -> 0 | AE11: =AD11*R11 -> 0
B12: =IV!B14 -> Name of vessel/Voy. | C12: =IV!C14 -> HF LUCKY 2617S | G12: =IV!H13 -> ETA Laem Chabang: On or about August 23rd 2026 | N12: 0618-1002-1 | O12: 8 | P12: kg | Q12: =SUMIF($B$19:$B$93,N12,$E$19:$E$123) -> 14 | R12: 1.65 | T12: 8 | U12: =T12*R12 -> 13.2 | V12: 4 | W12: =V12*R12 -> 6.6 | X12: 2 | Y12: =X12*R12 -> 3.3 | AA12: =Z12*R12 -> 0 | AC12: =R12*AB12 -> 0 | AE12: =AD12*R12 -> 0
B13: Sailing on: | C13: =IV!C15 -> August 19th 2026 | G13: Packing: Standard export packing | N13: 0618-087-2 | O13: 8 | P13: kg | Q13: =SUMIF($B$19:$B$93,N13,$E$19:$E$123) -> 2 | R13: 2.13 | U13: =T13*R13 -> 0 | V13: 2 | W13: =V13*R13 -> 4.26 | Y13: =X13*R13 -> 0 | AA13: =Z13*R13 -> 0 | AC13: =R13*AB13 -> 0 | AE13: =AD13*R13 -> 0
B14: Port of loading: | C14: Haiphong, Vietnam | N14: 618-084-13 | O14: 8 | P14: kg | Q14: =SUMIF($B$19:$B$93,N14,$E$19:$E$123) -> 0 | R14: 1.12 | U14: =T14*R14 -> 0 | W14: =V14*R14 -> 0 | Y14: =X14*R14 -> 0 | Z14: 8 | AA14: =Z14*R14 -> 8.96 | AC14: =R14*AB14 -> 0 | AE14: =AD14*R14 -> 0
B15: Port of discharge: | C15: Laem Chabang, Thailand | N15: 618-1005-03 | O15: 8 | P15: kg | Q15: =SUMIF($B$19:$B$93,N15,$E$19:$E$123) -> 0 | R15: 1.73 | U15: =T15*R15 -> 0 | V15: 5 | W15: =V15*R15 -> 8.65 | Y15: =X15*R15 -> 0 | AA15: =Z15*R15 -> 0 | AC15: =R15*AB15 -> 0 | AE15: =AD15*R15 -> 0
A17: Case No. | C17: Description of goods | E17: Quantity | G17: NW (Kgs) | H17: GW(Kgs) | I17: Remarks | Q17: =SUM(Q4:Q14) -> 68 | T17: =SUM(T4:T15) -> 24 | U17: =SUM(U4:U15) -> 26.72 | V17: =SUM(V4:V15) -> 19 | W17: =SUM(W4:W15) -> 24.07 | X17: =SUM(X4:X15) -> 27 | Y17: =SUM(Y4:Y15) -> 28.26 | Z17: =SUM(Z4:Z15) -> 27 | AA17: =SUM(AA4:AA15) -> 21.68 | ... AE17: =SUM(AE4:AE15) -> 0
A18: =[8]IV!A20 -> PARTS FOR CNC AUTOMATIC LATHE. | R18: Total case: | T18: =T17+V17+X17+Z17+AB17+AD17 -> 97
A19: 1~8 | B19: 618-089-4F | C19: BED | E19: 8 | F19: PCS | G19: =E19*L19 -> 4720 | H19: =G19+4*E19 -> 4752 | L19: =VLOOKUP(B19:B150,PO!C5:J139,8,0) -> 590 | R19: Total M3: | T19: =U17+W17+Y17+AA17+AC17+AE17 -> 100.73
A20: 9~16 | B20: 0618-1002-1 | C20: BED | E20: 8 | F20: PCS | G20: =E20*L20 -> 10640 | H20: =G20+4*E20 -> 10672 | L20: =VLOOKUP(B20:B151,PO!C6:J140,8,0) -> 1330
A21: 17~24 | B21: 0615-478 | C21: Z2 SLIDE | E21: 10 | F21: PCS | G21: =E21*L21 -> 300 | H21: =SUM(G21:G32)+39*8 -> 5881 | L21: =VLOOKUP(B21:B152,PO!C7:J141,8,0) -> 30
A22: 17~24 | B22: 0617-115-1 | C22: TOOL POST | E22: 10 | F22: PCS | G22: =E22*L22 -> 1410 | L22: =VLOOKUP(B22:B153,PO!C8:J142,8,0) -> 141
A23: 17~24 | B23: 0616-301-1 | C23: SLEEVE HOLDER | E23: 30 | F23: PCS | G23: =E23*L23 -> 390 | L23: =VLOOKUP(B23:B152,PO!C7:J141,8,0) -> 13
A24: 17~24 | B24: 0617-0011-1 | C24: TOOL POST | E24: 5 | F24: PCS | G24: =E24*L24 -> 675 | L24: =VLOOKUP(B24:B153,PO!C8:J142,8,0) -> 135
A25: 17~24 | B25: 0616-0019 | C25: CROSS SLIDE | E25: 10 | F25: PCS | G25: =E25*L25 -> 230 | I25: Cont 1 | J25: (40') | L25: =VLOOKUP(B25:B154,PO!C9:J143,8,0) -> 23
A26: 17~24 | B26: 0615-1002 | C26: Z2 SLIDE | E26: 15 | F26: PCS | G26: =E26*L26 -> 300 | I26: =$T$17 -> 24 | J26: Cases | L26: =VLOOKUP(B26:B155,PO!C10:J144,8,0) -> 20
A27: 17~24 | B27: 0615-1003-1 | C27: HEAD STOCK | E27: 15 | F27: PCS | G27: =E27*L27 -> 390 | I27: =$U$17 -> 26.72 | J27: M3 | L27: =VLOOKUP(B27:B156,PO!C11:J145,8,0) -> 26
A28: 17~24 | B28: 0617-1006-1 | C28: TOOL POST | E28: 5 | F28: PCS | G28: =E28*L28 -> 790 | L28: =VLOOKUP(B28:B157,PO!C12:J146,8,0) -> 158
A29: 17~24 | B29: 0615-1023 | C29: X-SLIDE | E29: 13 | F29: PCS | G29: =E29*L29 -> 221 | L29: =VLOOKUP(B29:B158,PO!C13:J147,8,0) -> 17
A30: 17~24 | B30: 0617-1007-1 | C30: CROSS SLIDE | E30: 10 | F30: PCS | G30: =E30*L30 -> 410 | L30: =VLOOKUP(B30:B159,PO!C14:J148,8,0) -> 41
A31: 17~24 | B31: 0615-1017 | C31: Z2 SLIDE | E31: 12 | F31: PCS | G31: =E31*L31 -> 348 | L31: =VLOOKUP(B31:B160,PO!C15:J149,8,0) -> 29
A32: 17~24 | B32: 0615-1018-1 | C32: Z2 SLIDE | E32: 5 | F32: PCS | G32: =E32*L32 -> 105 | L32: =VLOOKUP(B32:B161,PO!C16:J150,8,0) -> 21
A33: SUB TOTAL CONT 1 | E33: =SUM(E19:E32) -> 156 | F33: PCS | G33: =SUM(G19:G32) -> 20929 | H33: =SUM(H19:H32) -> 21305
A34: 1~2 | B34: 0618-087-2 | C34: BED | E34: 2 | F34: PCS | G34: =E34*L34 -> 2750 | H34: =G34+4*E34 -> 2758 | L34: =VLOOKUP(B34:B162,PO!C17:J151,8,0) -> 1375
A35: 3~6 | B35: 0618-1002-1 | C35: BED | E35: 4 | F35: PCS | G35: =E35*L35 -> 5320 | H35: =G35+4*E35 -> 5336 | L35: =VLOOKUP(B35:B164,PO!C19:J153,8,0) -> 1330
A36: 7~11 | B36: 618-1005-03F | C36: BED | E36: 5 | F36: PCS | G36: =E36*L36 -> 7940 | H36: =G36+4*E36 -> 7960 | L36: =VLOOKUP(B36:B165,PO!C20:J154,8,0) -> 1588
A37: 12~19 | B37: 0617-116-3 | C37: CROSS SLIDE | E37: 16 | F37: PCS | G37: =E37*L37 -> 736 | H37: =SUM(G37:G42)+39*8 -> 5406 | L37: =VLOOKUP(B37:B166,PO!C21:J155,8,0) -> 46
A38: =A37 -> 12~19 | B38: 0617-130-2 | C38: TOOL POST | E38: 3 | F38: PCS | G38: =E38*L38 -> 498 | I38: Cont 2 | J38: (40') | L38: =VLOOKUP(B38:B167,PO!C22:J156,8,0) -> 166
A39: =A38 -> 12~19 | B39: 0617-0011-1 | C39: TOOL POST | E39: 10 | F39: PCS | G39: =E39*L39 -> 1350 | I39: =$V$17 -> 19 | J39: Cases | L39: =VLOOKUP(B39:B168,PO!C23:J157,8,0) -> 135
A40: =A39 -> 12~19 | B40: 0617-1006-1 | C40: TOOL POST | E40: 10 | F40: PCS | G40: =E40*L40 -> 1580 | I40: =$W$17 -> 24.07 | J40: M3 | L40: =VLOOKUP(B40:B169,PO!C24:J158,8,0) -> 158
A41: =A40 -> 12~19 | B41: 0617-1005-1 | C41: CROSS SLIDE | E41: 10 | F41: PCS | G41: =E41*L41 -> 480 | L41: =VLOOKUP(B41:B170,PO!C25:J159,8,0) -> 48
...

Sheet VGM
A2: XÁC NHẬN TOÀN BỘ KHỐI LƯỢNG CONTAINER VẬN CHUYỂN QUỐC TẾ
A3: VERIFIED GROSS MASS SUBMISSION FORM (VGM FORM)
A5: 1/ Tên người gửi hàng (Shipper authorized name): CITIZEN MACHINERY VIETNAM CO., LTD
A6: 2/ Địa chỉ/ Số điện thoại (Adress/ Tel): Land plot J2, J3, J4, JAPAN HAIPHONG INDUSTRIAL ZONE-HONG AN -HAIPHONG, VIETNAM
C7: Tel: 84-225-3743232, 33 Fax: 84-225-3743234
A8: 3/ Thông số container (Container's particular):
A9: STT (No) | B9: SỐ BOOKING (Booking No) | C9: SỐ CONT (Cont No) | D9: LOẠI CONT (Size/Type) | E9: VGM (Kgs) | F9: NGÀY CÂN (VGM vertified date) | G9: TÊN ĐƠN VỊ VÀ ĐỊA CHỈ CÂN (Name of weighing scale, adress) | L9: GHI CHÚ (Remark)
A10: 1 | B10: EHPH26086690 | C10: =PL!C94 -> CAIU4156879 | D10: 40' | E10: =M10+N10 -> 24805 | F10: =TODAY() -> 46253 | G10: CITIZEN MACHINERY VIETNAM CO., LTD | M10: 3500 | N10: =PL!H33 -> 21305
A11: =A10+1 -> 2 | B11: =B10 -> EHPH26086690 | C11: =PL!C95 -> FCXU0014623 | D11: 40' | E11: =M11+N11 -> 24960 | F11: =TODAY() -> 46253 | G11: Adress: JAPAN HAIPHONG INDUSTRIAL ZONE, | M11: 3500 | N11: =PL!H43 -> 21460
A12: =A11+1 -> 3 | B12: =B11 -> EHPH26086690 | C12: =PL!C96 -> GVTU4038481 | D12: 40' | E12: =M12+N12 -> 25002 | F12: =TODAY() -> 46253 | G12: HONG AN, HAI PHONG | M12: 3520 | N12: =PL!H64 -> 21482
A13: =A12+1 -> 4 | B13: =B12 -> EHPH26086690 | C13: =PL!C97 -> TCNU4996836 | D13: 40' | E13: =M13+N13 -> 24607 | F13: =TODAY() -> 46253 | G13: HONG AN, HAI PHONG | M13: 3700 | N13: =PL!H87 -> 20907
A14: Chúng tôi cam kết và chịu trách nhiệm việc xác nhận toàn bộ khối lượng container như trên là đúng sự thật/ | N14: =SUM(N10:N13) -> 85154
A15: (We are committed to and respondsible for the VGM of the container ablove is true)
B17: ĐƠN VỊ CÂN / WEIGHING SCALE | F17: NGƯỜI GỬI HÀNG /SHIPPER

Sheet Sheet2
